{"uuid": "63780c66-892b-4f46-b79e-21f0182c30ab", "children": ["9466e366-f985-4ed4-9ef8-6e9b78ba1ab0"], "befores": [{"name": "fixtures_ver", "status": "broken", "statusDetails": {"message": "_pytest.outcomes.Exit: unable to communicate to ControllerHTTPSConnectionPool(host='sec-07ec963b.cicd.lab.wlan.tip.build', port=16001): Max retries exceeded with url: /api/v1/oauth2 (Caused by NewConnectionError('<urllib3.connection.HTTPSConnection object at 0x7fd258d86640>: Failed to establish a new connection: [Errno -5] No address associated with hostname'))\n", "trace": "  File \"/usr/local/lib/python3.8/site-packages/pluggy/callers.py\", line 187, in _multicall\n    res = hook_impl.function(*args)\n  File \"/usr/local/lib/python3.8/site-packages/_pytest/fixtures.py\", line 1126, in pytest_fixture_setup\n    result = call_fixture_func(fixturefunc, request, kwargs)\n  File \"/usr/local/lib/python3.8/site-packages/_pytest/fixtures.py\", line 925, in call_fixture_func\n    fixture_result = next(generator)\n  File \"/wlan-testing/tests/conftest.py\", line 646, in fixtures_ver\n    obj = Fixtures_2x(configuration=get_configuration)\n  File \"/wlan-testing/tests/fixtures_2x.py\", line 56, in __init__\n    pytest.exit(\"unable to communicate to Controller\" + str(e))\n  File \"/usr/local/lib/python3.8/site-packages/_pytest/outcomes.py\", line 115, in exit\n    raise Exit(msg, returncode)\n"}, "attachments": [{"name": "Controller Instantiation Failed: ", "source": "f0b90d91-2e8c-4f26-937a-11b2fa38f5c3-attachment.attach"}], "start": 1637269025068, "stop": 1637269025098}], "start": 1637269025068, "stop": 1637269029961}