{"uuid": "437558fb-1cfb-4431-8123-ad664fb719e6", "children": ["2c8ebc79-2096-4b77-a173-1abaae60c119"], "befores": [{"name": "get_ap_logs", "status": "passed", "start": 1635570580161, "stop": 1635570601761}], "afters": [{"name": "get_ap_logs::collect_logs", "status": "broken", "statusDetails": {"message": "paramiko.ssh_exception.NoValidConnectionsError: [Errno None] Unable to connect to port 22 on 10.28.3.100\n", "trace": "  File \"/usr/local/lib/python3.8/site-packages/allure_commons/_allure.py\", line 200, in __call__\n    return self._fixture_function(*args, **kwargs)\n  File \"/wlan-testing/tests/conftest.py\", line 655, in collect_logs\n    ap_ssh = get_apnos(ap, pwd=\"../libs/apnos/\", sdk=\"2.x\")\n  File \"/wlan-testing/tests/../libs/apnos/apnos.py\", line 42, in __init__\n    client = self.ssh_cli_connect()\n  File \"/wlan-testing/tests/../libs/apnos/apnos.py\", line 82, in ssh_cli_connect\n    client.connect(self.ip, username=self.username, password=self.password,\n  File \"/usr/local/lib/python3.8/site-packages/paramiko/client.py\", line 368, in connect\n    raise NoValidConnectionsError(errors)\n"}, "start": 1635570728338, "stop": 1635570729375}], "start": 1635570580161, "stop": 1635570729376}